Workbook
Name Slicer_Age_Group: #N/A
Name Slicer_Category: #N/A
Name Slicer_Country: #N/A
Name Slicer_Gender: #N/A
Name Slicer_Sales_Channel: #N/A

Sheet Dirty_Skincare_Data
A1: Order_ID | B1: Order_Date | C1: Product_ID | D1: Product_Name | E1: Category | F1: Brand | G1: Customer_ID | H1: Gender | I1: Age_Group | J1: Country | K1: Sales_Channel | L1: Quantity_Sold | M1: Cost_Price | N1: Selling_Price | O1: Discount_Percent | P1: Revenue | Q1: Profit | R1: Rating
A2: ORD1121 | B2: Jan 02 2025 | C2: P012 | D2: Sunscreen SPF50 | E2: Protection | F2: GlowBeauty | G2: C232 | H2: Male | I2: Teen | J2: Kenya | K2: Instagram | L2: 2 | M2: 10089 | N2: 12140 | O2: 0.02 | P2: 24280 | Q2: 4102 | R2: 2
A3: ORD1223 | B3: 08/06/2024 | C3: P010 | D3: Hydrating Cream | E3: Moisturizer | G3: C413 | H3: Male | I3: Young Adult | J3: Kenya | K3: WhatsApp | L3: 4 | M3: 13311 | N3: 17701 | O3: 0.04 | P3: 70804 | Q3: 17560 | R3: 3
A4: ORD1222 | B4: 20/07/2024 | C4: P008 | D4: Acne Cleanser | E4: Cleanser | F4: PureSkin | G4: C844 | H4: Female | I4: Adult | J4: nigeria | K4: Instagram | L4: 7 | M4: 3840 | N4: 9112 | O4: 0.1 | P4: 63784 | Q4: 36904 | R4: 4
A5: ORD1029 | B5: 2024-12-25 | C5: P002 | D5: vitamin c serum | E5: Serum | F5: GlowBeauty | G5: C675 | H5: Female | I5: Teen | J5: NIGERIA | K5: Website | L5: 7 | M5: 8462 | N5: 11456 | O5: 0 | P5: 80192 | Q5: 20958 | R5: 4
A6: ORD1039 | B6: Apr 22 2024 | C6: P012 | D6: Sunscreen SPF50 | E6: Protection | F6: GlowBeauty | G6: C156 | H6: Male | I6: Young Adult | J6: Ghana | K6: Retail | L6: 2 | M6: 14499 | N6: 15533 | O6: 0.04 | P6: 31066 | Q6: 2068 | R6: 4
A7: ORD1015 | B7: 2024-12-29 | C7: P014 | D7: Toner | E7: Other | F7: GlowBeauty | G7: C869 | H7: Male | I7: Young Adult | J7: NIGERIA | K7: Instagram | L7: 8 | M7: 6459 | N7: 11182 | O7: 0.04 | P7: 89456 | Q7: 37784 | R7: 4
A8: ORD1142 | B8: Jun 19 2024 | C8: P012 | D8: Sunscreen SPF50 | E8: Protection | F8: PureSkin | G8: C348 | H8: Male | I8: Teen | J8: Ghana | K8: Retail | L8: 2 | M8: 7078 | N8: 11343 | O8: 0.04 | P8: 22686 | Q8: 8530
A9: ORD1155 | B9: 08/03/2025 | C9: P015 | D9: Body Scrub | E9: Other | F9: glowbeauty | G9: C999 | H9: Female | I9: Adult | J9: Nigera | K9: Website | L9: 3 | M9: 14972 | N9: 19467 | O9: 0.04 | P9: 58401 | Q9: 13485 | R9: 5
A10: ORD1058 | B10: 2024-12-25 | C10: P017 | D10: Lip Balm | E10: Other | F10: GlowBeauty | G10: C193 | H10: Female | I10: Adult | J10: Nigera | K10: Instagram | L10: 4 | M10: 6626 | N10: 14222 | O10: 0.02 | P10: 56888 | Q10: 30384 | R10: 2
A11: ORD1201 | B11: Dec 09 2024 | C11: P001 | D11: Vitamin C Serum | E11: Serum | F11: GlowBeauty | G11: C136 | H11: Female | I11: Adult | J11: nigeria | K11: WhatsApp | L11: 2 | M11: 8180 | N11: 13636 | O11: 0.1 | P11: 27272 | Q11: 10912 | R11: 2
A12: ORD1091 | B12: 2025-03-24 | C12: P011 | D12: Night Cream | E12: Moisturizer | F12: PureSkin | G12: C962 | H12: Male | I12: Young Adult | J12: nigeria | K12: WhatsApp | L12: 8 | M12: 5153 | N12: 10367 | O12: 0.1 | P12: 82936 | Q12: 41712 | R12: 4
A13: ORD1064 | B13: Mar 26 2024 | C13: P012 | D13: Sunscreen SPF50 | E13: Protection | F13: SkinLab | G13: C787 | H13: Male | I13: Adult | J13: Ghana | K13: Website | L13: 4 | M13: 8734 | N13: 11969 | O13: 0.02 | P13: 47876 | Q13: 12940 | R13: 3
A14: ORD1062 | B14: Apr 11 2024 | C14: P004 | D14: Niacinamide Serum | E14: Serum | F14: DermaCare | G14: C210 | H14: Female | I14: Teen | J14: Nigera | K14: Retail | L14: 7 | M14: 12972 | N14: 19485 | O14: 0.1 | P14: 136395 | Q14: 45591 | R14: 5
A15: ORD1204 | B15: Oct 04 2024 | C15: P010 | D15: Hydrating Cream | E15: Moisturizer | F15: PureSkin | G15: C562 | H15: Female | I15: Teen | J15: Nigeria | K15: Retail | L15: 5 | M15: 13456 | N15: 15503 | O15: 0.1 | P15: 77515 | Q15: 10235 | R15: 5
A16: ORD1159 | B16: 18/08/2024 | C16: P006 | D16: Face Wash | E16: Cleanser | F16: SkinLab | G16: C341 | H16: Male | I16: Adult | J16: Nigeria | K16: Instagram | L16: 1 | M16: 11846 | N16: 18129 | O16: 0.04 | P16: 18129 | Q16: 6283 | R16: 3
A17: ORD1036 | B17: 14/03/2025 | C17: P014 | D17: Toner | E17: Other | G17: C548 | H17: Male | I17: Young Adult | J17: Kenya | K17: Website | L17: 4 | M17: 8422 | N17: 9879 | O17: 0.02 | P17: 39516 | Q17: 5828 | R17: 5
A18: ORD1209 | B18: 2025-02-22 | C18: P014 | D18: Toner | E18: Other | F18: GlowBeauty | G18: C917 | H18: Female | I18: Teen | J18: Ghana | K18: Website | L18: 2 | M18: 6301 | N18: 11672 | O18: 0.05 | P18: 23344 | Q18: 10742 | R18: 5
A19: ORD1242 | B19: 28/05/2024 | C19: P007 | D19: Deep Clean Cleanser | E19: Cleanser | F19: GlowBeauty | G19: C779 | H19: Female | I19: Young Adult | J19: South Africa | K19: WhatsApp | L19: 3 | M19: 2328 | N19: 8312 | O19: 0.04 | P19: 24936 | Q19: 17952 | R19: 2
A20: ORD1062 | B20: 2024-01-25 | C20: P007 | D20: Deep Clean Cleanser | E20: Cleanser | F20: DermaCare | G20: C661 | H20: Female | I20: Teen | J20: Kenya | K20: Instagram | L20: 4 | M20: 14129 | N20: 20076 | O20: 0.02 | P20: 80304 | Q20: 23788 | R20: 4
A21: ORD1157 | B21: 05/08/2024 | C21: P012 | D21: Sunscreen SPF50 | E21: Protection | F21: DermaCare | G21: C459 | H21: Male | I21: Adult | J21: Ghana | K21: Instagram | L21: 4 | M21: 9490 | N21: 15157 | O21: 0.1 | P21: 60628 | Q21: 22668 | R21: 1
A22: ORD1003 | B22: 24/01/2025 | C22: P012 | D22: Sunscreen SPF50 | E22: Protection | F22: SkinLab | G22: C396 | H22: Female | I22: Adult | J22: Nigera | K22: Website | L22: 8 | M22: 7273 | N22: 9493 | O22: 0.04 | P22: 75944 | Q22: 17760 | R22: 2
A23: ORD1034 | B23: Jan 21 2024 | C23: P018 | D23: Lip Scrub | E23: Other | F23: glowbeauty | G23: C773 | H23: Male | I23: Teen | J23: Kenya | K23: Instagram | L23: 6 | M23: 1818 | N23: 2683 | O23: 0.02 | P23: 16098 | Q23: 5190 | R23: 3
A24: ORD1067 | B24: Apr 29 2025 | C24: P004 | D24: Niacinamide Serum | E24: Serum | F24: SkinLab | G24: C569 | H24: Male | I24: Teen | J24: Nigeria | K24: Website | L24: 1 | M24: 10294 | N24: 14993 | O24: 0.04 | P24: 14993 | Q24: 4699 | R24: 5
A25: ORD1058 | B25: 10/10/2024 | C25: P002 | D25: vitamin c serum | E25: Serum | G25: C921 | H25: Female | I25: Teen | J25: nigeria | K25: WhatsApp | L25: 3 | M25: 14088 | N25: 19941 | O25: 0.1 | P25: 59823 | Q25: 17559
A26: ORD1085 | B26: 17/01/2024 | C26: P005 | D26: Retinol Serum | E26: Serum | F26: DermaCare | G26: C710 | H26: Male | I26: Adult | J26: Nigeria | K26: Instagram | L26: 6 | M26: 14958 | N26: 16291 | O26: 0.1 | P26: 97746 | Q26: 7998 | R26: 2
A27: ORD1143 | B27: 2024-05-22 | C27: P017 | D27: Lip Balm | E27: Other | F27: GlowBeauty | G27: C500 | H27: Female | I27: Adult | J27: NIGERIA | K27: Website | L27: 2 | M27: 1514 | N27: 9203 | O27: 0.1 | P27: 18406 | Q27: 15378 | R27: 4
A28: ORD1049 | B28: 2024-08-03 | C28: P003 | D28: Hyaluronic Acid Serum | E28: Serum | G28: C933 | H28: Male | I28: Teen | J28: nigeria | K28: Instagram | L28: 1 | M28: 14004 | N28: 15696 | O28: 0.04 | P28: 15696 | Q28: 1692 | R28: 4
A29: ORD1050 | B29: 2024-10-28 | C29: P008 | D29: Acne Cleanser | E29: Cleanser | F29: glowbeauty | G29: C695 | H29: Male | I29: Young Adult | J29: nigeria | K29: WhatsApp | L29: 2 | M29: 6906 | N29: 11708 | O29: 0.05 | P29: 23416 | Q29: 9604 | R29: 1
A30: ORD1021 | B30: 2024-08-02 | C30: P003 | D30: Hyaluronic Acid Serum | E30: Serum | F30: GlowBeauty | G30: C455 | H30: Female | I30: Adult | J30: Nigera | K30: Retail | L30: 3 | M30: 10224 | N30: 12730 | O30: 0 | P30: 38190 | Q30: 7518 | R30: 3
A31: ORD1007 | B31: 23/09/2024 | C31: P017 | D31: Lip Balm | E31: Other | F31: PureSkin | G31: C662 | H31: Male | I31: Teen | J31: South Africa | K31: Instagram | L31: 8 | M31: 10339 | N31: 11559 | O31: 0.04 | P31: 92472 | Q31: 9760 | R31: 5
A32: ORD1232 | B32: Nov 14 2024 | C32: P004 | D32: Niacinamide Serum | E32: Serum | G32: C247 | H32: Male | I32: Young Adult | J32: Nigera | K32: Instagram | L32: 6 | M32: 5400 | N32: 13318 | O32: 0.05 | P32: 79908 | Q32: 47508 | R32: 3
A33: ORD1229 | B33: May 06 2024 | C33: P001 | D33: Vitamin C Serum | E33: Serum | F33: GlowBeauty | G33: C303 | H33: Male | I33: Adult | J33: South Africa | K33: Retail | L33: 8 | M33: 11327 | N33: 18223 | O33: 0.05 | P33: 145784 | Q33: 55168 | R33: 1
A34: ORD1205 | B34: 2024-12-08 | C34: P014 | D34: Toner | E34: Other | F34: DermaCare | G34: C405 | H34: Female | I34: Adult | J34: South Africa | K34: WhatsApp | L34: 8 | M34: 13977 | N34: 18293 | O34: 0 | P34: 146344 | Q34: 34528 | R34: 1
A35: ORD1087 | B35: 2024-04-29 | C35: P008 | D35: Acne Cleanser | E35: Cleanser | G35: C791 | H35: Female | I35: Young Adult | J35: Nigeria | K35: Instagram | L35: 4 | M35: 13112 | N35: 13922 | O35: 0.02 | P35: 55688 | Q35: 3240 | R35: 4
A36: ORD1070 | B36: 22/05/2025 | C36: P010 | D36: Hydrating Cream | E36: Moisturizer | F36: DermaCare | G36: C305 | H36: Female | I36: Teen | J36: NIGERIA | K36: Instagram | L36: 5 | M36: 3653 | N36: 6965 | O36: 0.05 | P36: 34825 | Q36: 16560 | R36: 4
A37: ORD1234 | B37: 07/03/2025 | C37: P008 | D37: Acne Cleanser | E37: Cleanser | F37: SkinLab | G37: C970 | H37: Male | I37: Teen | J37: Nigera | K37: WhatsApp | L37: 4 | M37: 1463 | N37: 4907 | O37: 0.02 | P37: 19628 | Q37: 13776 | R37: 2
A38: ORD1142 | B38: 2024-11-10 | C38: P006 | D38: Face Wash | E38: Cleanser | G38: C331 | H38: Male | I38: Young Adult | J38: Nigera | K38: Instagram | L38: 8 | M38: 4947 | N38: 11572 | O38: 0.04 | P38: 92576 | Q38: 53000 | R38: 2
A39: ORD1128 | B39: Feb 21 2024 | C39: P002 | D39: vitamin c serum | E39: Serum | G39: C766 | H39: Male | I39: Teen | J39: Nigera | K39: WhatsApp | L39: 8 | M39: 14145 | N39: 21828 | O39: 0 | P39: 174624 | Q39: 61464 | R39: 3
A40: ORD1128 | B40: 2024-03-24 | C40: P014 | D40: Toner | E40: Other | F40: glowbeauty | G40: C491 | H40: Female | I40: Young Adult | J40: Kenya | K40: Instagram | L40: 4 | M40: 6665 | N40: 12111 | O40: 0 | P40: 48444 | Q40: 21784
...

Sheet Clean_Skincare_Data
A1: Order_ID | B1: Order_Date | C1: Product_ID | D1: Product_Name | E1: Category | F1: Brand | G1: Gender | H1: Age_Group | I1: Country | J1: Sales_Channel | K1: Quantity_Sold | L1: Cost_Price | M1: Total_Cost_Price | N1: Selling_Price | O1: Discount_Percent | P1: Revenue | Q1: Profit | R1: Rating
A2: ORD1001 | B2: 45659 | C2: P012 | D2: Sunscreen Spf50 | E2: Protection | F2: GlowBeauty | G2: Male | H2: Teen | I2: Kenya | J2: Instagram | K2: 2 | L2: 10089 | M2: =Table1[[#This Row],[Cost_Price]]*Table1[[#This Row],[Quantity_Sold]] -> 20178 | N2: 12140 | O2: 0.02 | P2: 24280 | Q2: 4102 | R2: 2
A3: ORD1002 | B3: 45451 | C3: P010 | D3: Hydrating Cream | E3: Moisturizer | F3: N/A | G3: Male | H3: Young Adult | I3: Kenya | J3: WhatsApp | K3: 4 | L3: 13311 | M3: =Table1[[#This Row],[Cost_Price]]*Table1[[#This Row],[Quantity_Sold]] -> 53244 | N3: 17701 | O3: 0.04 | P3: 70804 | Q3: 17560 | R3: 3
A4: ORD1003 | B4: 45493 | C4: P008 | D4: Acne Cleanser | E4: Cleanser | F4: PureSkin | G4: Female | H4: Adult | I4: Nigeria | J4: Instagram | K4: 7 | L4: 3840 | M4: =Table1[[#This Row],[Cost_Price]]*Table1[[#This Row],[Quantity_Sold]] -> 26880 | N4: 9112 | O4: 0.1 | P4: 63784 | Q4: 36904 | R4: 4
A5: ORD1004 | B5: 45651 | C5: P002 | D5: Vitamin C Serum | E5: Serum | F5: GlowBeauty | G5: Female | H5: Teen | I5: Nigeria | J5: Website | K5: 7 | L5: 8462 | M5: =Table1[[#This Row],[Cost_Price]]*Table1[[#This Row],[Quantity_Sold]] -> 59234 | N5: 11456 | O5: 0 | P5: 80192 | Q5: 20958 | R5: 4
A6: ORD1005 | B6: 45404 | C6: P012 | D6: Sunscreen Spf50 | E6: Protection | F6: GlowBeauty | G6: Male | H6: Young Adult | I6: Ghana | J6: Retail | K6: 2 | L6: 14499 | M6: =Table1[[#This Row],[Cost_Price]]*Table1[[#This Row],[Quantity_Sold]] -> 28998 | N6: 15533 | O6: 0.04 | P6: 31066 | Q6: 2068 | R6: 4
A7: ORD1006 | B7: 45655 | C7: P014 | D7: Toner | E7: Other | F7: GlowBeauty | G7: Male | H7: Young Adult | I7: Nigeria | J7: Instagram | K7: 8 | L7: 6459 | M7: =Table1[[#This Row],[Cost_Price]]*Table1[[#This Row],[Quantity_Sold]] -> 51672 | N7: 11182 | O7: 0.04 | P7: 89456 | Q7: 37784 | R7: 4
A8: ORD1007 | B8: 45462 | C8: P012 | D8: Sunscreen Spf50 | E8: Protection | F8: PureSkin | G8: Male | H8: Teen | I8: Ghana | J8: Retail | K8: 2 | L8: 7078 | M8: =Table1[[#This Row],[Cost_Price]]*Table1[[#This Row],[Quantity_Sold]] -> 14156 | N8: 11343 | O8: 0.04 | P8: 22686 | Q8: 8530 | R8: N/A
A9: ORD1008 | B9: 45724 | C9: P015 | D9: Body Scrub | E9: Other | F9: glowbeauty | G9: Female | H9: Adult | I9: Nigeria | J9: Website | K9: 3 | L9: 14972 | M9: =Table1[[#This Row],[Cost_Price]]*Table1[[#This Row],[Quantity_Sold]] -> 44916 | N9: 19467 | O9: 0.04 | P9: 58401 | Q9: 13485 | R9: 5
A10: ORD1009 | B10: 45651 | C10: P017 | D10: Lip Balm | E10: Other | F10: GlowBeauty | G10: Female | H10: Adult | I10: Nigeria | J10: Instagram | K10: 4 | L10: 6626 | M10: =Table1[[#This Row],[Cost_Price]]*Table1[[#This Row],[Quantity_Sold]] -> 26504 | N10: 14222 | O10: 0.02 | P10: 56888 | Q10: 30384 | R10: 2
A11: ORD1010 | B11: 45635 | C11: P001 | D11: Vitamin C Serum | E11: Serum | F11: GlowBeauty | G11: Female | H11: Adult | I11: Nigeria | J11: WhatsApp | K11: 2 | L11: 8180 | M11: =Table1[[#This Row],[Cost_Price]]*Table1[[#This Row],[Quantity_Sold]] -> 16360 | N11: 13636 | O11: 0.1 | P11: 27272 | Q11: 10912 | R11: 2
A12: ORD1011 | B12: 45740 | C12: P011 | D12: Night Cream | E12: Moisturizer | F12: PureSkin | G12: Male | H12: Young Adult | I12: Nigeria | J12: WhatsApp | K12: 8 | L12: 5153 | M12: =Table1[[#This Row],[Cost_Price]]*Table1[[#This Row],[Quantity_Sold]] -> 41224 | N12: 10367 | O12: 0.1 | P12: 82936 | Q12: 41712 | R12: 4
A13: ORD1012 | B13: 45377 | C13: P012 | D13: Sunscreen Spf50 | E13: Protection | F13: SkinLab | G13: Male | H13: Adult | I13: Ghana | J13: Website | K13: 4 | L13: 8734 | M13: =Table1[[#This Row],[Cost_Price]]*Table1[[#This Row],[Quantity_Sold]] -> 34936 | N13: 11969 | O13: 0.02 | P13: 47876 | Q13: 12940 | R13: 3
A14: ORD1013 | B14: 45393 | C14: P004 | D14: Niacinamide Serum | E14: Serum | F14: DermaCare | G14: Female | H14: Teen | I14: Nigeria | J14: Retail | K14: 7 | L14: 12972 | M14: =Table1[[#This Row],[Cost_Price]]*Table1[[#This Row],[Quantity_Sold]] -> 90804 | N14: 19485 | O14: 0.1 | P14: 136395 | Q14: 45591 | R14: 5
A15: ORD1014 | B15: 45569 | C15: P010 | D15: Hydrating Cream | E15: Moisturizer | F15: PureSkin | G15: Female | H15: Teen | I15: Nigeria | J15: Retail | K15: 5 | L15: 13456 | M15: =Table1[[#This Row],[Cost_Price]]*Table1[[#This Row],[Quantity_Sold]] -> 67280 | N15: 15503 | O15: 0.1 | P15: 77515 | Q15: 10235 | R15: 5
A16: ORD1015 | B16: 45522 | C16: P006 | D16: Face Wash | E16: Cleanser | F16: SkinLab | G16: Male | H16: Adult | I16: Nigeria | J16: Instagram | K16: 1 | L16: 11846 | M16: =Table1[[#This Row],[Cost_Price]]*Table1[[#This Row],[Quantity_Sold]] -> 11846 | N16: 18129 | O16: 0.04 | P16: 18129 | Q16: 6283 | R16: 3
A17: ORD1016 | B17: 45730 | C17: P014 | D17: Toner | E17: Other | F17: N/A | G17: Male | H17: Young Adult | I17: Kenya | J17: Website | K17: 4 | L17: 8422 | M17: =Table1[[#This Row],[Cost_Price]]*Table1[[#This Row],[Quantity_Sold]] -> 33688 | N17: 9879 | O17: 0.02 | P17: 39516 | Q17: 5828 | R17: 5
A18: ORD1017 | B18: 45710 | C18: P014 | D18: Toner | E18: Other | F18: GlowBeauty | G18: Female | H18: Teen | I18: Ghana | J18: Website | K18: 2 | L18: 6301 | M18: =Table1[[#This Row],[Cost_Price]]*Table1[[#This Row],[Quantity_Sold]] -> 12602 | N18: 11672 | O18: 0.05 | P18: 23344 | Q18: 10742 | R18: 5
A19: ORD1018 | B19: 45440 | C19: P007 | D19: Deep Clean Cleanser | E19: Cleanser | F19: GlowBeauty | G19: Female | H19: Young Adult | I19: South Africa | J19: WhatsApp | K19: 3 | L19: 2328 | M19: =Table1[[#This Row],[Cost_Price]]*Table1[[#This Row],[Quantity_Sold]] -> 6984 | N19: 8312 | O19: 0.04 | P19: 24936 | Q19: 17952 | R19: 2
A20: ORD1019 | B20: 45316 | C20: P007 | D20: Deep Clean Cleanser | E20: Cleanser | F20: DermaCare | G20: Female | H20: Teen | I20: Kenya | J20: Instagram | K20: 4 | L20: 14129 | M20: =Table1[[#This Row],[Cost_Price]]*Table1[[#This Row],[Quantity_Sold]] -> 56516 | N20: 20076 | O20: 0.02 | P20: 80304 | Q20: 23788 | R20: 4
... A24: ORD1023 | B24: 45776 | C24: P004 | D24: Niacinamide Serum | E24: Serum | F24: SkinLab | G24: Male | H24: Teen | I24: Nigeria | J24: Website | K24: 1 | L24: 10294 | M24: =Table1[[#This Row],[Cost_Price]]*Table1[[#This Row],[Quantity_Sold]] -> 10294 | N24: 14993 | O24: 0.04 | P24: 14993 | Q24: 4699 | R24: 5
A25: ORD1024 | B25: 45575 | C25: P002 | D25: Vitamin C Serum | E25: Serum | F25: N/A | G25: Female | H25: Teen | I25: Nigeria | J25: WhatsApp | K25: 3 | L25: 14088 | M25: =Table1[[#This Row],[Cost_Price]]*Table1[[#This Row],[Quantity_Sold]] -> 42264 | N25: 19941 | O25: 0.1 | P25: 59823 | Q25: 17559 | R25: N/A
A26: ORD1025 | B26: 45308 | C26: P005 | D26: Retinol Serum | E26: Serum | F26: DermaCare | G26: Male | H26: Adult | I26: Nigeria | J26: Instagram | K26: 6 | L26: 14958 | M26: =Table1[[#This Row],[Cost_Price]]*Table1[[#This Row],[Quantity_Sold]] -> 89748 | N26: 16291 | O26: 0.1 | P26: 97746 | Q26: 7998 | R26: 2
A27: ORD1026 | B27: 45434 | C27: P017 | D27: Lip Balm | E27: Other | F27: GlowBeauty | G27: Female | H27: Adult | I27: Nigeria | J27: Website | K27: 2 | L27: 1514 | M27: =Table1[[#This Row],[Cost_Price]]*Table1[[#This Row],[Quantity_Sold]] -> 3028 | N27: 9203 | O27: 0.1 | P27: 18406 | Q27: 15378 | R27: 4
A28: ORD1027 | B28: 45507 | C28: P003 | D28: Hyaluronic Acid Serum | E28: Serum | F28: N/A | G28: Male | H28: Teen | I28: Nigeria | J28: Instagram | K28: 1 | L28: 14004 | M28: =Table1[[#This Row],[Cost_Price]]*Table1[[#This Row],[Quantity_Sold]] -> 14004 | N28: 15696 | O28: 0.04 | P28: 15696 | Q28: 1692 | R28: 4
A29: ORD1028 | B29: 45593 | C29: P008 | D29: Acne Cleanser | E29: Cleanser | F29: glowbeauty | G29: Male | H29: Young Adult | I29: Nigeria | J29: WhatsApp | K29: 2 | L29: 6906 | M29: =Table1[[#This Row],[Cost_Price]]*Table1[[#This Row],[Quantity_Sold]] -> 13812 | N29: 11708 | O29: 0.05 | P29: 23416 | Q29: 9604 | R29: 1
A30: ORD1029 | B30: 45506 | C30: P003 | D30: Hyaluronic Acid Serum | E30: Serum | F30: GlowBeauty | G30: Female | H30: Adult | I30: Nigeria | J30: Retail | K30: 3 | L30: 10224 | M30: =Table1[[#This Row],[Cost_Price]]*Table1[[#This Row],[Quantity_Sold]] -> 30672 | N30: 12730 | O30: 0 | P30: 38190 | Q30: 7518 | R30: 3
A31: ORD1030 | B31: 45558 | C31: P017 | D31: Lip Balm | E31: Other | F31: PureSkin | G31: Male | H31: Teen | I31: South Africa | J31: Instagram | K31: 8 | L31: 10339 | M31: =Table1[[#This Row],[Cost_Price]]*Table1[[#This Row],[Quantity_Sold]] -> 82712 | N31: 11559 | O31: 0.04 | P31: 92472 | Q31: 9760 | R31: 5
A32: ORD1031 | B32: 45610 | C32: P004 | D32: Niacinamide Serum | E32: Serum | F32: N/A | G32: Male | H32: Young Adult | I32: Nigeria | J32: Instagram | K32: 6 | L32: 5400 | M32: =Table1[[#This Row],[Cost_Price]]*Table1[[#This Row],[Quantity_Sold]] -> 32400 | N32: 13318 | O32: 0.05 | P32: 79908 | Q32: 47508 | R32: 3
A33: ORD1032 | B33: 45418 | C33: P001 | D33: Vitamin C Serum | E33: Serum | F33: GlowBeauty | G33: Male | H33: Adult | I33: South Africa | J33: Retail | K33: 8 | L33: 11327 | M33: =Table1[[#This Row],[Cost_Price]]*Table1[[#This Row],[Quantity_Sold]] -> 90616 | N33: 18223 | O33: 0.05 | P33: 145784 | Q33: 55168 | R33: 1
A34: ORD1033 | B34: 45634 | C34: P014 | D34: Toner | E34: Other | F34: DermaCare | G34: Female | H34: Adult | I34: South Africa | J34: WhatsApp | K34: 8 | L34: 13977 | M34: =Table1[[#This Row],[Cost_Price]]*Table1[[#This Row],[Quantity_Sold]] -> 111816 | N34: 18293 | O34: 0 | P34: 146344 | Q34: 34528 | R34: 1
A35: ORD1034 | B35: 45411 | C35: P008 | D35: Acne Cleanser | E35: Cleanser | F35: N/A | G35: Female | H35: Young Adult | I35: Nigeria | J35: Instagram | K35: 4 | L35: 13112 | M35: =Table1[[#This Row],[Cost_Price]]*Table1[[#This Row],[Quantity_Sold]] -> 52448 | N35: 13922 | O35: 0.02 | P35: 55688 | Q35: 3240 | R35: 4
A36: ORD1035 | B36: 45799 | C36: P010 | D36: Hydrating Cream | E36: Moisturizer | F36: DermaCare | G36: Female | H36: Teen | I36: Nigeria | J36: Instagram | K36: 5 | L36: 3653 | M36: =Table1[[#This Row],[Cost_Price]]*Table1[[#This Row],[Quantity_Sold]] -> 18265 | N36: 6965 | O36: 0.05 | P36: 34825 | Q36: 16560 | R36: 4
A37: ORD1036 | B37: 45723 | C37: P008 | D37: Acne Cleanser | E37: Cleanser | F37: SkinLab | G37: Male | H37: Teen | I37: Nigeria | J37: WhatsApp | K37: 4 | L37: 1463 | M37: =Table1[[#This Row],[Cost_Price]]*Table1[[#This Row],[Quantity_Sold]] -> 5852 | N37: 4907 | O37: 0.02 | P37: 19628 | Q37: 13776 | R37: 2
... A39: ORD1038 | B39: 45343 | C39: P002 | D39: Vitamin C Serum | E39: Serum | F39: N/A | G39: Male | H39: Teen | I39: Nigeria | J39: WhatsApp | K39: 8 | L39: 14145 | M39: =Table1[[#This Row],[Cost_Price]]*Table1[[#This Row],[Quantity_Sold]] -> 113160 | N39: 21828 | O39: 0 | P39: 174624 | Q39: 61464 | R39: 3
A40: ORD1039 | B40: 45375 | C40: P014 | D40: Toner | E40: Other | F40: glowbeauty | G40: Female | H40: Young Adult | I40: Kenya | J40: Instagram | K40: 4 | L40: 6665 | M40: =Table1[[#This Row],[Cost_Price]]*Table1[[#This Row],[Quantity_Sold]] -> 26660 | N40: 12111 | O40: 0 | P40: 48444 | Q40: 21784 | R40: N/A
A41: ORD1040 | B41: 45501 | C41: P002 | D41: Vitamin C Serum | E41: Serum | F41: DermaCare | G41: Female | H41: Adult | I41: Ghana | J41: Instagram | K41: 8 | L41: 9303 | M41: =Table1[[#This Row],[Cost_Price]]*Table1[[#This Row],[Quantity_Sold]] -> 74424 | N41: 16713 | O41: 0.05 | P41: 133704 | Q41: 59280 | R41: 5
A42: ORD1041 | B42: 45397 | C42: P001 | D42: Vitamin C Serum | E42: Serum | F42: N/A | G42: Female | H42: Adult | I42: Nigeria | J42: Retail | K42: 3 | L42: 10239 | M42: =Table1[[#This Row],[Cost_Price]]*Table1[[#This Row],[Quantity_Sold]] -> 30717 | N42: 13735 | O42: 0.02 | P42: 41205 | Q42: 10488 | R42: 3
A43: ORD1042 | B43: 45321 | C43: P018 | D43: Lip Scrub | E43: Other | F43: SkinLab | G43: Female | H43: Adult | I43: Nigeria | J43: WhatsApp | K43: 5 | L43: 2729 | M43: =Table1[[#This Row],[Cost_Price]]*Table1[[#This Row],[Quantity_Sold]] -> 13645 | N43: 10615 | O43: 0.04 | P43: 53075 | Q43: 39430 | R43: N/A
A44: ORD1043 | B44: 45643 | C44: P011 | D44: Night Cream | E44: Moisturizer | F44: SkinLab | G44: Female | H44: Young Adult | I44: South Africa | J44: Website | K44: 2 | L44: 9127 | M44: =Table1[[#This Row],[Cost_Price]]*Table1[[#This Row],[Quantity_Sold]] -> 18254 | N44: 15035 | O44: 0.04 | P44: 30070 | Q44: 11816 | R44: 1
...

Sheet Product_Master
A1: Product_Name | B1: Avg_Cost_Price | C1: Avg_Selling_Price
A2: Sunscreen Spf50 | B2: =AVERAGEIFS(Clean_Skincare_Data!L:L, Clean_Skincare_Data!D:D, A2) -> 8386.7941 | C2: =AVERAGEIFS(Clean_Skincare_Data!N:N, Clean_Skincare_Data!D:D, A2) -> 12079.118
A3: Hydrating Cream | B3: =AVERAGEIFS(Clean_Skincare_Data!L:L, Clean_Skincare_Data!D:D, A3) -> 7565.9667 | C3: =AVERAGEIFS(Clean_Skincare_Data!N:N, Clean_Skincare_Data!D:D, A3) -> 12551.267
A4: Acne Cleanser | B4: =AVERAGEIFS(Clean_Skincare_Data!L:L, Clean_Skincare_Data!D:D, A4) -> 8217.625 | C4: =AVERAGEIFS(Clean_Skincare_Data!N:N, Clean_Skincare_Data!D:D, A4) -> 12092.5
A5: Vitamin C Serum | B5: =AVERAGEIFS(Clean_Skincare_Data!L:L, Clean_Skincare_Data!D:D, A5) -> 9404.2712 | C5: =AVERAGEIFS(Clean_Skincare_Data!N:N, Clean_Skincare_Data!D:D, A5) -> 14208.203
A6: Toner | B6: =AVERAGEIFS(Clean_Skincare_Data!L:L, Clean_Skincare_Data!D:D, A6) -> 9057 | C6: =AVERAGEIFS(Clean_Skincare_Data!N:N, Clean_Skincare_Data!D:D, A6) -> 12823.5
A7: Body Scrub | B7: =AVERAGEIFS(Clean_Skincare_Data!L:L, Clean_Skincare_Data!D:D, A7) -> 9310.8182 | C7: =AVERAGEIFS(Clean_Skincare_Data!N:N, Clean_Skincare_Data!D:D, A7) -> 13533.303
A8: Lip Balm | B8: =AVERAGEIFS(Clean_Skincare_Data!L:L, Clean_Skincare_Data!D:D, A8) -> 7710.5938 | C8: =AVERAGEIFS(Clean_Skincare_Data!N:N, Clean_Skincare_Data!D:D, A8) -> 11801.438
A9: Night Cream | B9: =AVERAGEIFS(Clean_Skincare_Data!L:L, Clean_Skincare_Data!D:D, A9) -> 7888.28 | C9: =AVERAGEIFS(Clean_Skincare_Data!N:N, Clean_Skincare_Data!D:D, A9) -> 12213.4
A10: Niacinamide Serum | B10: =AVERAGEIFS(Clean_Skincare_Data!L:L, Clean_Skincare_Data!D:D, A10) -> 8522 | C10: =AVERAGEIFS(Clean_Skincare_Data!N:N, Clean_Skincare_Data!D:D, A10) -> 12766.28
A11: Face Wash | B11: =AVERAGEIFS(Clean_Skincare_Data!L:L, Clean_Skincare_Data!D:D, A11) -> 6827.64 | C11: =AVERAGEIFS(Clean_Skincare_Data!N:N, Clean_Skincare_Data!D:D, A11) -> 11481.64
A12: Deep Clean Cleanser | B12: =AVERAGEIFS(Clean_Skincare_Data!L:L, Clean_Skincare_Data!D:D, A12) -> 8321.875 | C12: =AVERAGEIFS(Clean_Skincare_Data!N:N, Clean_Skincare_Data!D:D, A12) -> 12728.833
A13: Lip Scrub | B13: =AVERAGEIFS(Clean_Skincare_Data!L:L, Clean_Skincare_Data!D:D, A13) -> 8220.7857 | C13: =AVERAGEIFS(Clean_Skincare_Data!N:N, Clean_Skincare_Data!D:D, A13) -> 13188.536
... A18: Face Mask | B18: =AVERAGEIFS(Clean_Skincare_Data!L:L, Clean_Skincare_Data!D:D, A18) -> 7073.6087 | C18: =AVERAGEIFS(Clean_Skincare_Data!N:N, Clean_Skincare_Data!D:D, A18) -> 11118.696

Sheet Discount_Calculator
A1: SKINCARE DISCOUNT & PROFIT CALCULATOR
A2: Product Name | B2: Hydrating Cream
A3: Avg Cost Price | B3: =_xlfn.XLOOKUP(B2, Product_Master!A:A, Product_Master!B:B) -> 7565.9667
A4: Avg Selling Price | B4: =_xlfn.XLOOKUP(B2, Product_Master!A:A, Product_Master!C:C) -> 12551.267
A5: Discount % | B5: 0.0256
A6: Discount Amount | B6: =B4*B5 -> 321.31243
A7: Discounted Price | B7: =B4-B6 -> 12229.954
A8: Profit Before Discount | B8: =B4-B3 -> 4985.3
A9: Profit After Discount | B9: =B7-B3 -> 4663.9876
A12: Select a product and enter a discount percentage to evaluate the impact on profitability.

Sheet Pivot_Table
A1: Revenue by Product | G1: Profit by Product
A2: Row Labels | B2: Sum of Revenue | G2: Row Labels | H2: Sum of Profit
A3: Vitamin C Serum | B3: 3845198 | G3: Vitamin C Serum | H3: 1315511
A4: Retinol Serum | B4: 2131792 | G4: Hydrating Cream | H4: 756596
A5: Toner | B5: 2065190 | G5: Retinol Serum | H5: 734434
A6: Hydrating Cream | B6: 1956929 | G6: Body Scrub | H6: 648885
A7: Body Scrub | B7: 1937617 | G7: Night Cream | H7: 598764
A8: Lip Balm | B8: 1666053 | G8: Toner | H8: 578304
A9: Hyaluronic Acid Serum | B9: 1651656 | G9: Lip Scrub | H9: 572653
A10: Night Cream | B10: 1599345 | G10: Hyaluronic Acid Serum | H10: 569014
A11: Sunscreen Spf50 | B11: 1555526 | G11: Lip Balm | H11: 564561
A12: Lip Scrub | B12: 1460662 | G12: Face Wash | H12: 550040
A13: Deep Clean Cleanser | B13: 1436405 | G13: Sunscreen Spf50 | H13: 499118
A14: Niacinamide Serum | B14: 1344943 | G14: Niacinamide Serum | H14: 462783
... A20: Grand Total | B20: 28082936 | G20: Grand Total | H20: 9766653
A24: Revenue by Category | G24: Revenue by Sales Channel
A25: Row Labels | B25: Sum of Revenue | G25: Row Labels | H25: Sum of Revenue
A26: Serum | B26: 8973589 | G26: Instagram | H26: 7318188
A27: Other | B27: 8028694 | G27: Retail | H27: 7258247
A28: Moisturizer | B28: 4557133 | G28: Website | H28: 7114629
A29: Cleanser | B29: 4006027 | G29: WhatsApp | H29: 6391872
A30: Protection | B30: 2517493 | G30: Grand Total | H30: 28082936
A31: Grand Total | B31: 28082936
A39: Revenue by Country | G39: Quantity Sold by Age Group
A40: Row Labels | B40: Sum of Revenue | G40: Row Labels | H40: Sum of Quantity_Sold
A41: Nigeria | B41: 16290076 | G41: Teen | H41: 883
A42: South Africa | B42: 4732455 | G42: Adult | H42: 689
A43: Kenya | B43: 3581996 | G43: Young Adult | H43: 676
A44: Ghana | B44: 3478409 | G44: Grand Total | H44: 2248
A45: Grand Total | B45: 28082936
G54: KPI 1
A55: Revenue Over Time | G55: Sum of Revenue
A56: Row Labels | B56: Sum of Revenue | G56: 28082936
A57: Jan | B57: 2919448
A58: Feb | B58: 2716210 | G58: KPI 2
A59: Mar | B59: 3246292 | G59: Sum of Profit
A60: Apr | B60: 3356835 | G60: 9766653
A61: May | B61: 2982542
A62: Jun | B62: 3306122 | G62: KPI 3
A63: Jul | B63: 1976673 | G63: Sum of Quantity_Sold
...
